Workbook
Name BucketList: _xlfn.ANCHORARRAY(Summary!$AC$3)
Name CustomerList: _xlfn.ANCHORARRAY(Summary!$AA$3)
Name ProgramList: _xlfn.ANCHORARRAY(Summary!$AB$3)

Sheet Executive Summary
B1: Executive Summary
B2: This workbook presents a complete, end-to-end analytics workflow built from a 5,000-row synthetic operational dataset, demonstrating a full spectrum of data cleaning, transformation, summarization, and analytical modeling techniques applicable to technical program management and business operations. The Raw_Data sheet generates randomized customer, program, and timestamp activity designed to emulate real workloads across multiple product lines. From there, the Clean_Data sheet applies a structured cleaning pipeline that standardizes text fields, normalizes program and customer entries, reconstructs dates, classifies numerical ranges into buckets, and establishes quality checks through a TextCheck and Data_Quality_Flag system. These steps ensure the data is consistent, analyzable, and suitable for downstream processing.
B4: The Analysis sheet expands on the cleaned dataset with focused calculations, including value bucket assignments, summary checks, and aggregated metrics that support multi-dimensional analysis. The workbook uses modern Excel features—including LET, UNIQUE, SORT, FILTER, INDEX, XLOOKUP, and dynamic arrays—to maintain a reactive model in which changes to the raw input immediately flow through all dependent structures. The Summary sheet compiles these components into clear, logical groupings such as monthly totals, yearly totals, customer-level aggregates, program distributions, and bucket analyses. These summaries are fully dynamic and reflect the current state of the Clean_Data sheet without requiring manual refresh.
B6: The workbook concludes with early-stage visualization outputs on the Visualizations and Heatmap sheets. The heatmap provides a pivot-based distribution view of Value1 across customers and programs, enabling quick pattern recognition and concentration analysis. The visualization framework on the Visualizations sheet establishes space and structure for charts and dashboards that can be expanded to present trends, distribution profiles, customer contribution analysis, and value segmentation. Together, the sheets form a cohesive analytical foundation that transforms raw, inconsistent operational data into reliable business insights.

Sheet Documentation
B2: Project Overview
B3: This workbook demonstrates an end-to-end analytics workflow using a synthetic 5,000-row operational dataset. The goal is to showcase practical skills in data cleaning, transformation, summarization, and visualization—mirroring the type of analysis used in technical program management, operations, product readiness, and customer analytics work.
B5: Problem Statement
B6: Operational datasets often arrive in inconsistent, unstructured, or partially incorrect formats. To support decision-making and reporting, messy raw data must be standardized, validated, and summarized into clean, reliable insights.
B8: This workbook simulates that workflow by transforming noisy raw input into a structured analytics layer that enables accurate reporting and portfolio-level understanding.
B10: Solution Approach
B11: 1. Raw Data Generation (Raw_Data)
B12: Built a synthetic dataset with randomized Customer, Program, Value1, Value2, and Date fields.
B13: Ensured variation across 15 customers and 4 programs, mirroring multi-product operational workloads.
B14: The raw data intentionally includes mixed text formatting, inconsistent capitalization, and varied date forms—typical of real-world operational inputs.
B16: 2. Data Cleaning Pipeline (Clean_Data)
B17: Applied a structured sequence of transformations:
... B67: These capabilities apply directly to technical program management, operations analytics, readiness tracking, and cross-functional reporting.

Sheet Raw_Data
A1: ID | B1: Customer | C1: Program | D1: Value1 | E1: Value2 | F1: Date
A2: 1 | B2: Customer 6 | C2: Desktop | D2: 739 | E2: 2715 | F2: 45292
A3: 2 | B3: Customer 2 | C3: Workstation | D3: 2352 | E3: 914 | F3: 45292.042
A4: 3 | B4: Customer 8 | C4: Desktop | D4: 2493 | E4: 690 | F4: 45292.083
A5: 4 | B5: Customer 13 | C5: Workstation | D5: 3095 | E5: 1498 | F5: 45292.125
A6: 5 | B6: Customer 13 | C6: Embedded | D6: 772 | E6: 4731 | F6: 45292.167
A7: 6 | B7: Customer 13 | C7: Workstation | D7: 445 | E7: 4144 | F7: 45292.208
A8: 7 | B8: Customer 6 | C8: Embedded | D8: 515 | E8: 4101 | F8: 45292.25
A9: 8 | B9: Customer 8 | C9: Desktop | D9: 2609 | E9: 692 | F9: 45292.292
A10: 9 | B10: Customer 10 | C10: Embedded | D10: 2566 | E10: 4161 | F10: 45292.333
A11: 10 | B11: Customer 2 | C11: Embedded | D11: 3239 | E11: 3993 | F11: 45292.375
A12: 11 | B12: Customer 6 | C12: Workstation | D12: 3089 | E12: 1494 | F12: 45292.417
A13: 12 | B13: Customer 12 | C13: Embedded | D13: 960 | E13: 1749 | F13: 45292.458
... A5001: 5000 | B5001: Customer 14 | C5001: Mobile | D5001: 1517 | E5001: 2668 | F5001: 45500.292

Sheet Clean_Data
A1: ID | B1: Customer | C1: Program | D1: Value1 | E1: Value2 | F1: Date | G1: Customer_Clean | H1: Program_Clean | I1: TextCheck | J1: Value1 Clean | K1: Value2 Clean | L1: Date Clean | M1: Date QA | N1: Priority | O1: Data_Quality_Flag | P1: Final_ID | Q1: Final_Customer | R1: Final_Program | S1: Final_Value1 | T1: Final_Value2 | U1: Final_Date | V1: Value1_Bucket | W1: Month_Key | X1: Year_Num
A2: ='Raw_Data'!A2 -> 1 | B2: ='Raw_Data'!B2 -> Customer 6 | C2: ='Raw_Data'!C2 -> Desktop | D2: ='Raw_Data'!D2 -> 739 | E2: ='Raw_Data'!E2 -> 2715 | F2: ='Raw_Data'!F2 -> 45292 | G2: =PROPER(CLEAN(TRIM(B2))) -> Customer 6 | H2: =UPPER(CLEAN(TRIM(C2))) -> DESKTOP | I2: =IF(OR(NOT(EXACT(B2,G2)), NOT(EXACT(C2,H2))), "Changed", "") -> Changed | J2: =IFERROR(VALUE(TRIM(D2)), "") -> 739 | K2: =IFERROR(VALUE(TRIM(E2)), "") -> 2715 | L2: =IF(F2="","",INT(F2)) -> 45292 | M2: =IF(AND(L2>=DATE(2000,1,1), L2<=TODAY()+365), "OK", "OutOfRange") -> OK | P2: =IF(A2="","",A2) -> 1 | Q2: =IF(G2="","",G2) -> Customer 6 | R2: =IF(H2="","",H2) -> DESKTOP | S2: =IF(J2="","",J2) -> 739 | T2: =IF(K2="","",K2) -> 2715 | U2: =IF(L2="","",L2) -> 45292 | V2: {=_xlfn.IFS(S2 = "", "", S2 < 500, "Low", S2 < 1200, "Medium", TRUE, "High")} -> Medium | W2: =TEXT(U2, "yyyy-mm") -> 2024-01 | X2: =YEAR(U2) -> 2024
A3: ='Raw_Data'!A3 -> 2 | B3: ='Raw_Data'!B3 -> Customer 2 | C3: ='Raw_Data'!C3 -> Workstation | D3: ='Raw_Data'!D3 -> 2352 | E3: ='Raw_Data'!E3 -> 914 | F3: ='Raw_Data'!F3 -> 45292.042 | G3: =PROPER(CLEAN(TRIM(B3))) -> Customer 2 | H3: =UPPER(CLEAN(TRIM(C3))) -> WORKSTATION | I3: =IF(OR(NOT(EXACT(B3,G3)), NOT(EXACT(C3,H3))), "Changed", "") -> Changed | J3: =IFERROR(VALUE(TRIM(D3)), "") -> 2352 | K3: =IFERROR(VALUE(TRIM(E3)), "") -> 914 | L3: =IF(F3="","",INT(F3)) -> 45292 | M3: =IF(AND(L3>=DATE(2000,1,1), L3<=TODAY()+365), "OK", "OutOfRange") -> OK | P3: =IF(A3="","",A3) -> 2 | Q3: =IF(G3="","",G3) -> Customer 2 | R3: =IF(H3="","",H3) -> WORKSTATION | S3: =IF(J3="","",J3) -> 2352 | T3: =IF(K3="","",K3) -> 914 | U3: =IF(L3="","",L3) -> 45292 | V3: {=_xlfn.IFS(S3 = "", "", S3 < 500, "Low", S3 < 1200, "Medium", TRUE, "High")} -> High | W3: =TEXT(U3, "yyyy-mm") -> 2024-01 | X3: =YEAR(U3) -> 2024
A4: ='Raw_Data'!A4 -> 3 | B4: ='Raw_Data'!B4 -> Customer 8 | C4: ='Raw_Data'!C4 -> Desktop | D4: ='Raw_Data'!D4 -> 2493 | E4: ='Raw_Data'!E4 -> 690 | F4: ='Raw_Data'!F4 -> 45292.083 | G4: =PROPER(CLEAN(TRIM(B4))) -> Customer 8 | H4: =UPPER(CLEAN(TRIM(C4))) -> DESKTOP | I4: =IF(OR(NOT(EXACT(B4,G4)), NOT(EXACT(C4,H4))), "Changed", "") -> Changed | J4: =IFERROR(VALUE(TRIM(D4)), "") -> 2493 | K4: =IFERROR(VALUE(TRIM(E4)), "") -> 690 | L4: =IF(F4="","",INT(F4)) -> 45292 | M4: =IF(AND(L4>=DATE(2000,1,1), L4<=TODAY()+365), "OK", "OutOfRange") -> OK | P4: =IF(A4="","",A4) -> 3 | Q4: =IF(G4="","",G4) -> Customer 8 | R4: =IF(H4="","",H4) -> DESKTOP | S4: =IF(J4="","",J4) -> 2493 | T4: =IF(K4="","",K4) -> 690 | U4: =IF(L4="","",L4) -> 45292 | V4: {=_xlfn.IFS(S4 = "", "", S4 < 500, "Low", S4 < 1200, "Medium", TRUE, "High")} -> High | W4: =TEXT(U4, "yyyy-mm") -> 2024-01 | X4: =YEAR(U4) -> 2024
A5: ='Raw_Data'!A5 -> 4 | B5: ='Raw_Data'!B5 -> Customer 13 | C5: ='Raw_Data'!C5 -> Workstation | D5: ='Raw_Data'!D5 -> 3095 | E5: ='Raw_Data'!E5 -> 1498 | F5: ='Raw_Data'!F5 -> 45292.125 | G5: =PROPER(CLEAN(TRIM(B5))) -> Customer 13 | H5: =UPPER(CLEAN(TRIM(C5))) -> WORKSTATION | I5: =IF(OR(NOT(EXACT(B5,G5)), NOT(EXACT(C5,H5))), "Changed", "") -> Changed | J5: =IFERROR(VALUE(TRIM(D5)), "") -> 3095 | K5: =IFERROR(VALUE(TRIM(E5)), "") -> 1498 | L5: =IF(F5="","",INT(F5)) -> 45292 | M5: =IF(AND(L5>=DATE(2000,1,1), L5<=TODAY()+365), "OK", "OutOfRange") -> OK | P5: =IF(A5="","",A5) -> 4 | Q5: =IF(G5="","",G5) -> Customer 13 | R5: =IF(H5="","",H5) -> WORKSTATION | S5: =IF(J5="","",J5) -> 3095 | T5: =IF(K5="","",K5) -> 1498 | U5: =IF(L5="","",L5) -> 45292 | V5: {=_xlfn.IFS(S5 = "", "", S5 < 500, "Low", S5 < 1200, "Medium", TRUE, "High")} -> High | W5: =TEXT(U5, "yyyy-mm") -> 2024-01 | X5: =YEAR(U5) -> 2024
A6: ='Raw_Data'!A6 -> 5 | B6: ='Raw_Data'!B6 -> Customer 13 | C6: ='Raw_Data'!C6 -> Embedded | D6: ='Raw_Data'!D6 -> 772 | E6: ='Raw_Data'!E6 -> 4731 | F6: ='Raw_Data'!F6 -> 45292.167 | G6: =PROPER(CLEAN(TRIM(B6))) -> Customer 13 | H6: =UPPER(CLEAN(TRIM(C6))) -> EMBEDDED | I6: =IF(OR(NOT(EXACT(B6,G6)), NOT(EXACT(C6,H6))), "Changed", "") -> Changed | J6: =IFERROR(VALUE(TRIM(D6)), "") -> 772 | K6: =IFERROR(VALUE(TRIM(E6)), "") -> 4731 | L6: =IF(F6="","",INT(F6)) -> 45292 | M6: =IF(AND(L6>=DATE(2000,1,1), L6<=TODAY()+365), "OK", "OutOfRange") -> OK | P6: =IF(A6="","",A6) -> 5 | Q6: =IF(G6="","",G6) -> Customer 13 | R6: =IF(H6="","",H6) -> EMBEDDED | S6: =IF(J6="","",J6) -> 772 | T6: =IF(K6="","",K6) -> 4731 | U6: =IF(L6="","",L6) -> 45292 | V6: {=_xlfn.IFS(S6 = "", "", S6 < 500, "Low", S6 < 1200, "Medium", TRUE, "High")} -> Medium | W6: =TEXT(U6, "yyyy-mm") -> 2024-01 | X6: =YEAR(U6) -> 2024
A7: ='Raw_Data'!A7 -> 6 | B7: ='Raw_Data'!B7 -> Customer 13 | C7: ='Raw_Data'!C7 -> Workstation | D7: ='Raw_Data'!D7 -> 445 | E7: ='Raw_Data'!E7 -> 4144 | F7: ='Raw_Data'!F7 -> 45292.208 | G7: =PROPER(CLEAN(TRIM(B7))) -> Customer 13 | H7: =UPPER(CLEAN(TRIM(C7))) -> WORKSTATION | I7: =IF(OR(NOT(EXACT(B7,G7)), NOT(EXACT(C7,H7))), "Changed", "") -> Changed | J7: =IFERROR(VALUE(TRIM(D7)), "") -> 445 | K7: =IFERROR(VALUE(TRIM(E7)), "") -> 4144 | L7: =IF(F7="","",INT(F7)) -> 45292 | M7: =IF(AND(L7>=DATE(2000,1,1), L7<=TODAY()+365), "OK", "OutOfRange") -> OK | P7: =IF(A7="","",A7) -> 6 | Q7: =IF(G7="","",G7) -> Customer 13 | R7: =IF(H7="","",H7) -> WORKSTATION | S7: =IF(J7="","",J7) -> 445 | T7: =IF(K7="","",K7) -> 4144 | U7: =IF(L7="","",L7) -> 45292 | V7: {=_xlfn.IFS(S7 = "", "", S7 < 500, "Low", S7 < 1200, "Medium", TRUE, "High")} -> Low | W7: =TEXT(U7, "yyyy-mm") -> 2024-01 | X7: =YEAR(U7) -> 2024
A8: ='Raw_Data'!A8 -> 7 | B8: ='Raw_Data'!B8 -> Customer 6 | C8: ='Raw_Data'!C8 -> Embedded | D8: ='Raw_Data'!D8 -> 515 | E8: ='Raw_Data'!E8 -> 4101 | F8: ='Raw_Data'!F8 -> 45292.25 | G8: =PROPER(CLEAN(TRIM(B8))) -> Customer 6 | H8: =UPPER(CLEAN(TRIM(C8))) -> EMBEDDED | I8: =IF(OR(NOT(EXACT(B8,G8)), NOT(EXACT(C8,H8))), "Changed", "") -> Changed | J8: =IFERROR(VALUE(TRIM(D8)), "") -> 515 | K8: =IFERROR(VALUE(TRIM(E8)), "") -> 4101 | L8: =IF(F8="","",INT(F8)) -> 45292 | M8: =IF(AND(L8>=DATE(2000,1,1), L8<=TODAY()+365), "OK", "OutOfRange") -> OK | P8: =IF(A8="","",A8) -> 7 | Q8: =IF(G8="","",G8) -> Customer 6 | R8: =IF(H8="","",H8) -> EMBEDDED | S8: =IF(J8="","",J8) -> 515 | T8: =IF(K8="","",K8) -> 4101 | U8: =IF(L8="","",L8) -> 45292 | V8: {=_xlfn.IFS(S8 = "", "", S8 < 500, "Low", S8 < 1200, "Medium", TRUE, "High")} -> Medium | W8: =TEXT(U8, "yyyy-mm") -> 2024-01 | X8: =YEAR(U8) -> 2024
A9: ='Raw_Data'!A9 -> 8 | B9: ='Raw_Data'!B9 -> Customer 8 | C9: ='Raw_Data'!C9 -> Desktop | D9: ='Raw_Data'!D9 -> 2609 | E9: ='Raw_Data'!E9 -> 692 | F9: ='Raw_Data'!F9 -> 45292.292 | G9: =PROPER(CLEAN(TRIM(B9))) -> Customer 8 | H9: =UPPER(CLEAN(TRIM(C9))) -> DESKTOP | I9: =IF(OR(NOT(EXACT(B9,G9)), NOT(EXACT(C9,H9))), "Changed", "") -> Changed | J9: =IFERROR(VALUE(TRIM(D9)), "") -> 2609 | K9: =IFERROR(VALUE(TRIM(E9)), "") -> 692 | L9: =IF(F9="","",INT(F9)) -> 45292 | M9: =IF(AND(L9>=DATE(2000,1,1), L9<=TODAY()+365), "OK", "OutOfRange") -> OK | P9: =IF(A9="","",A9) -> 8 | Q9: =IF(G9="","",G9) -> Customer 8 | R9: =IF(H9="","",H9) -> DESKTOP | S9: =IF(J9="","",J9) -> 2609 | T9: =IF(K9="","",K9) -> 692 | U9: =IF(L9="","",L9) -> 45292 | V9: {=_xlfn.IFS(S9 = "", "", S9 < 500, "Low", S9 < 1200, "Medium", TRUE, "High")} -> High | W9: =TEXT(U9, "yyyy-mm") -> 2024-01 | X9: =YEAR(U9) -> 2024
A10: ='Raw_Data'!A10 -> 9 | B10: ='Raw_Data'!B10 -> Customer 10 | C10: ='Raw_Data'!C10 -> Embedded | D10: ='Raw_Data'!D10 -> 2566 | E10: ='Raw_Data'!E10 -> 4161 | F10: ='Raw_Data'!F10 -> 45292.333 | G10: =PROPER(CLEAN(TRIM(B10))) -> Customer 10 | H10: =UPPER(CLEAN(TRIM(C10))) -> EMBEDDED | I10: =IF(OR(NOT(EXACT(B10,G10)), NOT(EXACT(C10,H10))), "Changed", "") -> Changed | J10: =IFERROR(VALUE(TRIM(D10)), "") -> 2566 | K10: =IFERROR(VALUE(TRIM(E10)), "") -> 4161 | L10: =IF(F10="","",INT(F10)) -> 45292 | M10: =IF(AND(L10>=DATE(2000,1,1), L10<=TODAY()+365), "OK", "OutOfRange") -> OK | P10: =IF(A10="","",A10) -> 9 | Q10: =IF(G10="","",G10) -> Customer 10 | R10: =IF(H10="","",H10) -> EMBEDDED | S10: =IF(J10="","",J10) -> 2566 | T10: =IF(K10="","",K10) -> 4161 | U10: =IF(L10="","",L10) -> 45292 | V10: {=_xlfn.IFS(S10 = "", "", S10 < 500, "Low", S10 < 1200, "Medium", TRUE, "High")} -> High | W10: =TEXT(U10, "yyyy-mm") -> 2024-01 | X10: =YEAR(U10) -> 2024
A11: ='Raw_Data'!A11 -> 10 | B11: ='Raw_Data'!B11 -> Customer 2 | C11: ='Raw_Data'!C11 -> Embedded | D11: ='Raw_Data'!D11 -> 3239 | E11: ='Raw_Data'!E11 -> 3993 | F11: ='Raw_Data'!F11 -> 45292.375 | G11: =PROPER(CLEAN(TRIM(B11))) -> Customer 2 | H11: =UPPER(CLEAN(TRIM(C11))) -> EMBEDDED | I11: =IF(OR(NOT(EXACT(B11,G11)), NOT(EXACT(C11,H11))), "Changed", "") -> Changed | J11: =IFERROR(VALUE(TRIM(D11)), "") -> 3239 | K11: =IFERROR(VALUE(TRIM(E11)), "") -> 3993 | L11: =IF(F11="","",INT(F11)) -> 45292 | M11: =IF(AND(L11>=DATE(2000,1,1), L11<=TODAY()+365), "OK", "OutOfRange") -> OK | P11: =IF(A11="","",A11) -> 10 | Q11: =IF(G11="","",G11) -> Customer 2 | R11: =IF(H11="","",H11) -> EMBEDDED | S11: =IF(J11="","",J11) -> 3239 | T11: =IF(K11="","",K11) -> 3993 | U11: =IF(L11="","",L11) -> 45292 | V11: {=_xlfn.IFS(S11 = "", "", S11 < 500, "Low", S11 < 1200, "Medium", TRUE, "High")} -> High | W11: =TEXT(U11, "yyyy-mm") -> 2024-01 | X11: =YEAR(U11) -> 2024
A12: ='Raw_Data'!A12 -> 11 | B12: ='Raw_Data'!B12 -> Customer 6 | C12: ='Raw_Data'!C12 -> Workstation | D12: ='Raw_Data'!D12 -> 3089 | E12: ='Raw_Data'!E12 -> 1494 | F12: ='Raw_Data'!F12 -> 45292.417 | G12: =PROPER(CLEAN(TRIM(B12))) -> Customer 6 | H12: =UPPER(CLEAN(TRIM(C12))) -> WORKSTATION | I12: =IF(OR(NOT(EXACT(B12,G12)), NOT(EXACT(C12,H12))), "Changed", "") -> Changed | J12: =IFERROR(VALUE(TRIM(D12)), "") -> 3089 | K12: =IFERROR(VALUE(TRIM(E12)), "") -> 1494 | L12: =IF(F12="","",INT(F12)) -> 45292 | M12: =IF(AND(L12>=DATE(2000,1,1), L12<=TODAY()+365), "OK", "OutOfRange") -> OK | P12: =IF(A12="","",A12) -> 11 | Q12: =IF(G12="","",G12) -> Customer 6 | R12: =IF(H12="","",H12) -> WORKSTATION | S12: =IF(J12="","",J12) -> 3089 | T12: =IF(K12="","",K12) -> 1494 | U12: =IF(L12="","",L12) -> 45292 | V12: {=_xlfn.IFS(S12 = "", "", S12 < 500, "Low", S12 < 1200, "Medium", TRUE, "High")} -> High | W12: =TEXT(U12, "yyyy-mm") -> 2024-01 | X12: =YEAR(U12) -> 2024
A13: ='Raw_Data'!A13 -> 12 | B13: ='Raw_Data'!B13 -> Customer 12 | C13: ='Raw_Data'!C13 -> Embedded | D13: ='Raw_Data'!D13 -> 960 | E13: ='Raw_Data'!E13 -> 1749 | F13: ='Raw_Data'!F13 -> 45292.458 | G13: =PROPER(CLEAN(TRIM(B13))) -> Customer 12 | H13: =UPPER(CLEAN(TRIM(C13))) -> EMBEDDED | I13: =IF(OR(NOT(EXACT(B13,G13)), NOT(EXACT(C13,H13))), "Changed", "") -> Changed | J13: =IFERROR(VALUE(TRIM(D13)), "") -> 960 | K13: =IFERROR(VALUE(TRIM(E13)), "") -> 1749 | L13: =IF(F13="","",INT(F13)) -> 45292 | M13: =IF(AND(L13>=DATE(2000,1,1), L13<=TODAY()+365), "OK", "OutOfRange") -> OK | P13: =IF(A13="","",A13) -> 12 | Q13: =IF(G13="","",G13) -> Customer 12 | R13: =IF(H13="","",H13) -> EMBEDDED | S13: =IF(J13="","",J13) -> 960 | T13: =IF(K13="","",K13) -> 1749 | U13: =IF(L13="","",L13) -> 45292 | V13: {=_xlfn.IFS(S13 = "", "", S13 < 500, "Low", S13 < 1200, "Medium", TRUE, "High")} -> Medium | W13: =TEXT(U13, "yyyy-mm") -> 2024-01 | X13: =YEAR(U13) -> 2024
... A5001: ='Raw_Data'!A5001 -> 5000 | B5001: ='Raw_Data'!B5001 -> Customer 14 | C5001: ='Raw_Data'!C5001 -> Mobile | D5001: ='Raw_Data'!D5001 -> 1517 | E5001: ='Raw_Data'!E5001 -> 2668 | F5001: ='Raw_Data'!F5001 -> 45500.292 | G5001: =PROPER(CLEAN(TRIM(B5001))) -> Customer 14 | H5001: =UPPER(CLEAN(TRIM(C5001))) -> MOBILE | I5001: =IF(OR(NOT(EXACT(B5001,G5001)), NOT(EXACT(C5001,H5001))), "Changed", "") -> Changed | J5001: =IFERROR(VALUE(TRIM(D5001)), "") -> 1517 | K5001: =IFERROR(VALUE(TRIM(E5001)), "") -> 2668 | L5001: =IF(F5001="","",INT(F5001)) -> 45500 | M5001: =IF(AND(L5001>=DATE(2000,1,1), L5001<=TODAY()+365), "OK", "OutOfRange") -> OK | P5001: =IF(A5001="","",A5001) -> 5000 | Q5001: =IF(G5001="","",G5001) -> Customer 14 | R5001: =IF(H5001="","",H5001) -> MOBILE | S5001: =IF(J5001="","",J5001) -> 1517 | T5001: =IF(K5001="","",K5001) -> 2668 | U5001: =IF(L5001="","",L5001) -> 45500 | V5001: {=_xlfn.IFS(S5001 = "", "", S5001 < 500, "Low", S5001 < 1200, "Medium", TRUE, "High")} -> High | W5001: =TEXT(U5001, "yyyy-mm") -> 2024-07 | X5001: =YEAR(U5001) -> 2024

Sheet Analysis
A2: Lookup ID | B2: 1 | D2: Filter Customer | E2: Customer 1 | K2: Unique Customers | L2: Unique Programs | M2: Value1 Buckets | O2: All Data - Sorted by Date (Ascending) | W2: All Data – Sorted by Value1 (Descending) | AE2: Customer & Program - Sorted by Value1 (Descending) | AL2: Value1 Bucket Filter | AM2: Medium
D3: Filter Program | E3: Desktop | K3: {=_xlfn.UNIQUE(Clean_Data!$Q:$Q)} -> Final_Customer | L3: {=_xlfn.UNIQUE(Clean_Data!$R:$R)} -> Final_Program | M3: {=_xlfn.UNIQUE(Clean_Data!$V:$V)} -> Value1_Bucket | O3: Final_ID | P3: Final_Customer | Q3: Final_Program | R3: Final_Value1 | S3: Final_Value2 | T3: Final_Date | W3: Final_ID | X3: Final_Customer | Y3: Final_Program | Z3: Final_Value1 | AA3: Final_Value2 | AB3: Final_Date | AE3: Final_ID | AF3: Final_Customer | AG3: Final_Program | AH3: Final_Value1 | AI3: Final_Value2 | AJ3: Final_Date
A4: Customer | B4: =_xlfn.XLOOKUP($B$2, Clean_Data!$P:$P, Clean_Data!$Q:$Q, "ID not found") -> Customer 6 | K4: Customer 6 | L4: DESKTOP | M4: Medium | O4: {=_xlfn._xlws.SORT(Clean_Data!$P$2:$U$5001, 6, 1)} -> 1 | P4: Customer 6 | Q4: DESKTOP | R4: 739 | S4: 2715 | T4: 45292 | W4: {=_xlfn._xlws.SORT(Clean_Data!$P$2:$U$5001, 4, -1)} -> 514 | X4: Customer 9 | Y4: MOBILE | Z4: 4000 | AA4: 4777 | AB4: 45313 | AE4: {=_xlfn._xlws.SORT(_xlfn._xlws.FILTER(Clean_Data!$P$2:$U$5001, (Clean_Data!$Q$2:$Q$5001 = $E$6) * (Clean_Data!$R$2:$R$5001 = $F$6), "No rows match"),4,-1)} -> 386 | AF4: Customer 1 | AG4: DESKTOP | AH4: 3987 | AI4: 2892 | AJ4: 45308 | AM4: Rows in Selected Value Bucket (Low, Med, High), Sorted by Value1 Descending
A5: Program | B5: =_xlfn.XLOOKUP($B$2, Clean_Data!$P:$P, Clean_Data!$R:$R, "ID not found") -> DESKTOP | D5: Final_ID | E5: Final_Customer | F5: Final_Program | G5: Final_Value1 | H5: Final_Value2 | I5: Final_Date | K5: Customer 2 | L5: WORKSTATION | M5: High | O5: 2 | P5: Customer 2 | Q5: WORKSTATION | R5: 2352 | S5: 914 | T5: 45292 | W5: 3611 | X5: Customer 12 | Y5: MOBILE | Z5: 4000 | AA5: 990 | AB5: 45442 | AE5: 3839 | AF5: Customer 1 | AG5: DESKTOP | AH5: 3920 | AI5: 3373 | AJ5: 45451 | AM5: Final_ID | AN5: Final_Customer | AO5: Final_Program | AP5: Final_Value1 | AQ5: Final_Value2 | AR5: Final_Date
A6: Value1 | B6: =_xlfn.XLOOKUP($B$2, Clean_Data!$P:$P, Clean_Data!$S:$S, "ID not found") -> 739 | D6: {=_xlfn._xlws.FILTER(Clean_Data!$P:$U, (Clean_Data!$Q:$Q = $E$2) * (Clean_Data!$R:$R = $E$3), "No rows match")} -> 96 | E6: Customer 1 | F6: DESKTOP | G6: 1628 | H6: 1946 | I6: 45295 | K6: Customer 8 | L6: EMBEDDED | M6: Low | O6: 3 | P6: Customer 8 | Q6: DESKTOP | R6: 2493 | S6: 690 | T6: 45292 | W6: 3847 | X6: Customer 13 | Y6: MOBILE | Z6: 4000 | AA6: 3410 | AB6: 45452 | AE6: 4228 | AF6: Customer 1 | AG6: DESKTOP | AH6: 3885 | AI6: 3776 | AJ6: 45468 | AM6: {=_xlfn._xlws.SORT(_xlfn._xlws.FILTER(Clean_Data!$P$2:$U$5001, Clean_Data!$V$2:$V$5001 = $AM$2, "No rows in this bucket"), 4, -1)} -> 3360 | AN6: Customer 10 | AO6: WORKSTATION | AP6: 1199 | AQ6: 1759 | AR6: 45431
A7: Value2 | B7: =_xlfn.XLOOKUP($B$2, Clean_Data!$P:$P, Clean_Data!$T:$T, "ID not found") -> 2715 | D7: 218 | E7: Customer 1 | F7: DESKTOP | G7: 3070 | H7: 3704 | I7: 45301 | K7: Customer 13 | L7: MOBILE | M7: 0 | O7: 4 | P7: Customer 13 | Q7: WORKSTATION | R7: 3095 | S7: 1498 | T7: 45292 | W7: 3476 | X7: Customer 13 | Y7: WORKSTATION | Z7: 3999 | AA7: 4459 | AB7: 45436 | AE7: 2506 | AF7: Customer 1 | AG7: DESKTOP | AH7: 3841 | AI7: 1655 | AJ7: 45396 | AM7: 3737 | AN7: Customer 8 | AO7: EMBEDDED | AP7: 1199 | AQ7: 4500 | AR7: 45447
A8: Date | B8: =_xlfn.XLOOKUP($B$2, Clean_Data!$P:$P, Clean_Data!$U:$U, "ID not found") -> 45292 | D8: 225 | E8: Customer 1 | F8: DESKTOP | G8: 2132 | H8: 3952 | I8: 45301 | K8: Customer 10 | L8: 0 | O8: 5 | P8: Customer 13 | Q8: EMBEDDED | R8: 772 | S8: 4731 | T8: 45292 | W8: 4806 | X8: Customer 7 | Y8: DESKTOP | Z8: 3998 | AA8: 1428 | AB8: 45492 | AE8: 4019 | AF8: Customer 1 | AG8: DESKTOP | AH8: 3765 | AI8: 332 | AJ8: 45459 | AM8: 1780 | AN8: Customer 11 | AO8: DESKTOP | AP8: 1198 | AQ8: 3452 | AR8: 45366
A9: Value1 Bucket | B9: =_xlfn.XLOOKUP($B$2, Clean_Data!$P:$P, Clean_Data!$V:$V, "ID not found") -> Medium | D9: 386 | E9: Customer 1 | F9: DESKTOP | G9: 3987 | H9: 2892 | I9: 45308 | K9: Customer 12 | O9: 6 | P9: Customer 13 | Q9: WORKSTATION | R9: 445 | S9: 4144 | T9: 45292 | W9: 3260 | X9: Customer 11 | Y9: EMBEDDED | Z9: 3997 | AA9: 2519 | AB9: 45427 | AE9: 1219 | AF9: Customer 1 | AG9: DESKTOP | AH9: 3743 | AI9: 2419 | AJ9: 45342 | AM9: 3460 | AN9: Customer 3 | AO9: DESKTOP | AP9: 1198 | AQ9: 2219 | AR9: 45436
D10: 391 | E10: Customer 1 | F10: DESKTOP | G10: 3427 | H10: 3145 | I10: 45308 | K10: Customer 11 | O10: 7 | P10: Customer 6 | Q10: EMBEDDED | R10: 515 | S10: 4101 | T10: 45292 | W10: 174 | X10: Customer 2 | Y10: DESKTOP | Z10: 3996 | AA10: 4378 | AB10: 45299 | AE10: 1022 | AF10: Customer 1 | AG10: DESKTOP | AH10: 3737 | AI10: 2242 | AJ10: 45334 | AM10: 3462 | AN10: Customer 3 | AO10: DESKTOP | AP10: 1198 | AQ10: 2538 | AR10: 45436
D11: 433 | E11: Customer 1 | F11: DESKTOP | G11: 1190 | H11: 3615 | I11: 45310 | K11: Customer 1 | O11: 8 | P11: Customer 8 | Q11: DESKTOP | R11: 2609 | S11: 692 | T11: 45292 | W11: 659 | X11: Customer 13 | Y11: DESKTOP | Z11: 3996 | AA11: 4332 | AB11: 45319 | AE11: 1149 | AF11: Customer 1 | AG11: DESKTOP | AH11: 3711 | AI11: 886 | AJ11: 45339 | AM11: 3902 | AN11: Customer 11 | AO11: MOBILE | AP11: 1198 | AQ11: 3140 | AR11: 45454
D12: 448 | E12: Customer 1 | F12: DESKTOP | G12: 897 | H12: 2944 | I12: 45310 | K12: Customer 15 | O12: 9 | P12: Customer 10 | Q12: EMBEDDED | R12: 2566 | S12: 4161 | T12: 45292 | W12: 2805 | X12: Customer 13 | Y12: DESKTOP | Z12: 3996 | AA12: 1391 | AB12: 45408 | AE12: 467 | AF12: Customer 1 | AG12: DESKTOP | AH12: 3676 | AI12: 705 | AJ12: 45311 | AM12: 2206 | AN12: Customer 11 | AO12: WORKSTATION | AP12: 1196 | AQ12: 2041 | AR12: 45383
D13: 452 | E13: Customer 1 | F13: DESKTOP | G13: 3287 | H13: 3004 | I13: 45310 | K13: Customer 14 | O13: 10 | P13: Customer 2 | Q13: EMBEDDED | R13: 3239 | S13: 3993 | T13: 45292 | W13: 4516 | X13: Customer 12 | Y13: MOBILE | Z13: 3996 | AA13: 2537 | AB13: 45480 | AE13: 2369 | AF13: Customer 1 | AG13: DESKTOP | AH13: 3642 | AI13: 3222 | AJ13: 45390 | AM13: 762 | AN13: Customer 10 | AO13: WORKSTATION | AP13: 1195 | AQ13: 3708 | AR13: 45323
D14: 467 | E14: Customer 1 | F14: DESKTOP | G14: 3676 | H14: 705 | I14: 45311 | K14: Customer 5 | O14: 11 | P14: Customer 6 | Q14: WORKSTATION | R14: 3089 | S14: 1494 | T14: 45292 | W14: 4202 | X14: Customer 4 | Y14: EMBEDDED | Z14: 3995 | AA14: 296 | AB14: 45467 | AE14: 3434 | AF14: Customer 1 | AG14: DESKTOP | AH14: 3642 | AI14: 2147 | AJ14: 45435 | AM14: 1004 | AN14: Customer 13 | AO14: WORKSTATION | AP14: 1195 | AQ14: 2752 | AR14: 45333
D15: 533 | E15: Customer 1 | F15: DESKTOP | G15: 2694 | H15: 667 | I15: 45314 | K15: Customer 9 | O15: 12 | P15: Customer 12 | Q15: EMBEDDED | R15: 960 | S15: 1749 | T15: 45292 | W15: 3313 | X15: Customer 2 | Y15: DESKTOP | Z15: 3993 | AA15: 4813 | AB15: 45429 | AE15: 2127 | AF15: Customer 1 | AG15: DESKTOP | AH15: 3579 | AI15: 138 | AJ15: 45380 | AM15: 1662 | AN15: Customer 10 | AO15: WORKSTATION | AP15: 1192 | AQ15: 4903 | AR15: 45361
D16: 552 | E16: Customer 1 | F16: DESKTOP | G16: 3314 | H16: 1727 | I16: 45314 | K16: Customer 3 | O16: 13 | P16: Customer 13 | Q16: DESKTOP | R16: 3936 | S16: 1759 | T16: 45292 | W16: 949 | X16: Customer 5 | Y16: DESKTOP | Z16: 3992 | AA16: 4577 | AB16: 45331 | AE16: 1574 | AF16: Customer 1 | AG16: DESKTOP | AH16: 3530 | AI16: 523 | AJ16: 45357 | AM16: 986 | AN16: Customer 4 | AO16: WORKSTATION | AP16: 1191 | AQ16: 1660 | AR16: 45333
D17: 557 | E17: Customer 1 | F17: DESKTOP | G17: 2171 | H17: 2237 | I17: 45315 | K17: Customer 7 | O17: 14 | P17: Customer 2 | Q17: EMBEDDED | R17: 2878 | S17: 1029 | T17: 45292 | W17: 2873 | X17: Customer 1 | Y17: EMBEDDED | Z17: 3990 | AA17: 330 | AB17: 45411 | AE17: 1499 | AF17: Customer 1 | AG17: DESKTOP | AH17: 3516 | AI17: 2813 | AJ17: 45354 | AM17: 4285 | AN17: Customer 11 | AO17: MOBILE | AP17: 1191 | AQ17: 3127 | AR17: 45470
D18: 596 | E18: Customer 1 | F18: DESKTOP | G18: 635 | H18: 3540 | I18: 45316 | K18: Customer 4 | O18: 15 | P18: Customer 6 | Q18: DESKTOP | R18: 2297 | S18: 196 | T18: 45292 | W18: 930 | X18: Customer 6 | Y18: MOBILE | Z18: 3989 | AA18: 4535 | AB18: 45330 | AE18: 3553 | AF18: Customer 1 | AG18: DESKTOP | AH18: 3503 | AI18: 3378 | AJ18: 45439 | AM18: 433 | AN18: Customer 1 | AO18: DESKTOP | AP18: 1190 | AQ18: 3615 | AR18: 45310
D19: 625 | E19: Customer 1 | F19: DESKTOP | G19: 1239 | H19: 650 | I19: 45318 | K19: 0 | O19: 16 | P19: Customer 11 | Q19: DESKTOP | R19: 2066 | S19: 2484 | T19: 45292 | W19: 1757 | X19: Customer 2 | Y19: MOBILE | Z19: 3989 | AA19: 1025 | AB19: 45365 | AE19: 1129 | AF19: Customer 1 | AG19: DESKTOP | AH19: 3477 | AI19: 4635 | AJ19: 45339 | AM19: 4618 | AN19: Customer 12 | AO19: EMBEDDED | AP19: 1190 | AQ19: 286 | AR19: 45484
D20: 717 | E20: Customer 1 | F20: DESKTOP | G20: 124 | H20: 4197 | I20: 45321 | O20: 17 | P20: Customer 13 | Q20: EMBEDDED | R20: 1890 | S20: 187 | T20: 45292 | W20: 2571 | X20: Customer 11 | Y20: DESKTOP | Z20: 3989 | AA20: 2053 | AB20: 45399 | AE20: 391 | AF20: Customer 1 | AG20: DESKTOP | AH20: 3427 | AI20: 3145 | AJ20: 45308 | AM20: 2248 | AN20: Customer 1 | AO20: DESKTOP | AP20: 1189 | AQ20: 4277 | AR20: 45385
D21: 858 | E21: Customer 1 | F21: DESKTOP | G21: 3371 | H21: 4471 | I21: 45327 | O21: 18 | P21: Customer 2 | Q21: WORKSTATION | R21: 296 | S21: 1298 | T21: 45292 | W21: 2652 | X21: Customer 9 | Y21: DESKTOP | Z21: 3988 | AA21: 2836 | AB21: 45402 | AE21: 858 | AF21: Customer 1 | AG21: DESKTOP | AH21: 3371 | AI21: 4471 | AJ21: 45327 | AM21: 1515 | AN21: Customer 1 | AO21: DESKTOP | AP21: 1187 | AQ21: 3692 | AR21: 45355
D22: 900 | E22: Customer 1 | F22: DESKTOP | G22: 1972 | H22: 4834 | I22: 45329 | O22: 19 | P22: Customer 2 | Q22: EMBEDDED | R22: 3586 | S22: 3356 | T22: 45292 | W22: 386 | X22: Customer 1 | Y22: DESKTOP | Z22: 3987 | AA22: 2892 | AB22: 45308 | AE22: 2668 | AF22: Customer 1 | AG22: DESKTOP | AH22: 3359 | AI22: 1630 | AJ22: 45403 | AM22: 1866 | AN22: Customer 3 | AO22: EMBEDDED | AP22: 1186 | AQ22: 193 | AR22: 45369
D23: 1022 | E23: Customer 1 | F23: DESKTOP | G23: 3737 | H23: 2242 | I23: 45334 | O23: 20 | P23: Customer 11 | Q23: MOBILE | R23: 1098 | S23: 761 | T23: 45292 | W23: 3744 | X23: Customer 7 | Y23: DESKTOP | Z23: 3987 | AA23: 4078 | AB23: 45447 | AE23: 552 | AF23: Customer 1 | AG23: DESKTOP | AH23: 3314 | AI23: 1727 | AJ23: 45314 | AM23: 1693 | AN23: Customer 12 | AO23: WORKSTATION | AP23: 1185 | AQ23: 1573 | AR23: 45362
D24: 1113 | E24: Customer 1 | F24: DESKTOP | G24: 2213 | H24: 3582 | I24: 45338 | O24: 21 | P24: Customer 12 | Q24: MOBILE | R24: 2489 | S24: 3227 | T24: 45292 | W24: 3985 | X24: Customer 7 | Y24: MOBILE | Z24: 3987 | AA24: 1520 | AB24: 45457 | AE24: 452 | AF24: Customer 1 | AG24: DESKTOP | AH24: 3287 | AI24: 3004 | AJ24: 45310 | AM24: 2797 | AN24: Customer 12 | AO24: WORKSTATION | AP24: 1185 | AQ24: 1762 | AR24: 45408
D25: 1122 | E25: Customer 1 | F25: DESKTOP | G25: 650 | H25: 3646 | I25: 45338 | O25: 22 | P25: Customer 12 | Q25: WORKSTATION | R25: 2047 | S25: 428 | T25: 45292 | W25: 1704 | X25: Customer 9 | Y25: MOBILE | Z25: 3986 | AA25: 2597 | AB25: 45362 | AE25: 3114 | AF25: Customer 1 | AG25: DESKTOP | AH25: 3272 | AI25: 4904 | AJ25: 45421 | AM25: 4678 | AN25: Customer 9 | AO25: EMBEDDED | AP25: 1185 | AQ25: 4475 | AR25: 45486
D26: 1129 | E26: Customer 1 | F26: DESKTOP | G26: 3477 | H26: 4635 | I26: 45339 | O26: 23 | P26: Customer 12 | Q26: EMBEDDED | R26: 47 | S26: 3994 | T26: 45292 | W26: 4630 | X26: Customer 6 | Y26: WORKSTATION | Z26: 3985 | AA26: 3510 | AB26: 45484 | AE26: 4163 | AF26: Customer 1 | AG26: DESKTOP | AH26: 3179 | AI26: 4321 | AJ26: 45465 | AM26: 131 | AN26: Customer 9 | AO26: EMBEDDED | AP26: 1184 | AQ26: 1909 | AR26: 45297
D27: 1149 | E27: Customer 1 | F27: DESKTOP | G27: 3711 | H27: 886 | I27: 45339 | O27: 24 | P27: Customer 1 | Q27: WORKSTATION | R27: 3946 | S27: 4484 | T27: 45292 | W27: 2219 | X27: Customer 12 | Y27: WORKSTATION | Z27: 3984 | AA27: 2046 | AB27: 45384 | AE27: 218 | AF27: Customer 1 | AG27: DESKTOP | AH27: 3070 | AI27: 3704 | AJ27: 45301 | AM27: 246 | AN27: Customer 3 | AO27: WORKSTATION | AP27: 1184 | AQ27: 1373 | AR27: 45302
D28: 1219 | E28: Customer 1 | F28: DESKTOP | G28: 3743 | H28: 2419 | I28: 45342 | O28: 25 | P28: Customer 15 | Q28: DESKTOP | R28: 699 | S28: 3249 | T28: 45293 | W28: 2383 | X28: Customer 10 | Y28: DESKTOP | Z28: 3984 | AA28: 2841 | AB28: 45391 | AE28: 1421 | AF28: Customer 1 | AG28: DESKTOP | AH28: 3067 | AI28: 4371 | AJ28: 45351 | AM28: 474 | AN28: Customer 7 | AO28: WORKSTATION | AP28: 1181 | AQ28: 2327 | AR28: 45311
D29: 1223 | E29: Customer 1 | F29: DESKTOP | G29: 2452 | H29: 2880 | I29: 45342 | O29: 26 | P29: Customer 14 | Q29: WORKSTATION | R29: 2376 | S29: 4567 | T29: 45293 | W29: 4064 | X29: Customer 13 | Y29: EMBEDDED | Z29: 3983 | AA29: 1480 | AB29: 45461 | AE29: 2544 | AF29: Customer 1 | AG29: DESKTOP | AH29: 3015 | AI29: 2945 | AJ29: 45397 | AM29: 3420 | AN29: Customer 8 | AO29: DESKTOP | AP29: 1181 | AQ29: 1361 | AR29: 45434
D30: 1232 | E30: Customer 1 | F30: DESKTOP | G30: 631 | H30: 4830 | I30: 45343 | O30: 27 | P30: Customer 5 | Q30: DESKTOP | R30: 1037 | S30: 1877 | T30: 45293 | W30: 4781 | X30: Customer 8 | Y30: DESKTOP | Z30: 3983 | AA30: 587 | AB30: 45491 | AE30: 4832 | AF30: Customer 1 | AG30: DESKTOP | AH30: 2973 | AI30: 4830 | AJ30: 45493 | AM30: 695 | AN30: Customer 7 | AO30: EMBEDDED | AP30: 1180 | AQ30: 4288 | AR30: 45320
D31: 1235 | E31: Customer 1 | F31: DESKTOP | G31: 365 | H31: 4712 | I31: 45343 | O31: 28 | P31: Customer 9 | Q31: EMBEDDED | R31: 3962 | S31: 1382 | T31: 45293 | W31: 616 | X31: Customer 5 | Y31: DESKTOP | Z31: 3982 | AA31: 373 | AB31: 45317 | AE31: 4952 | AF31: Customer 1 | AG31: DESKTOP | AH31: 2917 | AI31: 1994 | AJ31: 45498 | AM31: 2773 | AN31: Customer 14 | AO31: MOBILE | AP31: 1180 | AQ31: 4931 | AR31: 45407
... D112: 4952 | E112: Customer 1 | F112: DESKTOP | G112: 2917 | H112: 1994 | I112: 45498 | O112: 111 | P112: Customer 12 | Q112: MOBILE | R112: 2948 | S112: 3445 | T112: 45296 | W112: 3555 | X112: Customer 8 | Y112: EMBEDDED | Z112: 3923 | AA112: 3893 | AB112: 45440 | AE112: 4999 | AF112: Customer 1 | AG112: DESKTOP | AH112: 34 | AI112: 451 | AJ112: 45500 | AM112: 3818 | AN112: Customer 13 | AO112: WORKSTATION | AP112: 1121 | AQ112: 4618 | AR112: 45451
D113: 4959 | E113: Customer 1 | F113: DESKTOP | G113: 2653 | H113: 716 | I113: 45498 | O113: 112 | P113: Customer 10 | Q113: WORKSTATION | R113: 1742 | S113: 3000 | T113: 45296 | W113: 4624 | X113: Customer 14 | Y113: MOBILE | Z113: 3923 | AA113: 1490 | AB113: 45484 | AM113: 364 | AN113: Customer 5 | AO113: WORKSTATION | AP113: 1120 | AQ113: 2687 | AR113: 45307
D114: 4999 | E114: Customer 1 | F114: DESKTOP | G114: 34 | H114: 451 | I114: 45500 | O114: 113 | P114: Customer 9 | Q114: MOBILE | R114: 1723 | S114: 1265 | T114: 45296 | W114: 120 | X114: Customer 15 | Y114: MOBILE | Z114: 3921 | AA114: 145 | AB114: 45296 | AM114: 3044 | AN114: Customer 10 | AO114: WORKSTATION | AP114: 1120 | AQ114: 1238 | AR114: 45418
O115: 114 | P115: Customer 5 | Q115: EMBEDDED | R115: 3238 | S115: 2926 | T115: 45296 | W115: 3839 | X115: Customer 1 | Y115: DESKTOP | Z115: 3920 | AA115: 3373 | AB115: 45451 | AM115: 3319 | AN115: Customer 3 | AO115: DESKTOP | AP115: 1120 | AQ115: 440 | AR115: 45430
O116: 115 | P116: Customer 15 | Q116: WORKSTATION | R116: 1662 | S116: 1483 | T116: 45296 | W116: 4268 | X116: Customer 5 | Y116: WORKSTATION | Z116: 3919 | AA116: 2871 | AB116: 45469 | AM116: 682 | AN116: Customer 11 | AO116: MOBILE | AP116: 1119 | AQ116: 979 | AR116: 45320
O117: 116 | P117: Customer 9 | Q117: DESKTOP | R117: 3199 | S117: 3956 | T117: 45296 | W117: 783 | X117: Customer 9 | Y117: MOBILE | Z117: 3916 | AA117: 2228 | AB117: 45324 | AM117: 2931 | AN117: Customer 1 | AO117: MOBILE | AP117: 1119 | AQ117: 226 | AR117: 45414
O118: 117 | P118: Customer 7 | Q118: MOBILE | R118: 850 | S118: 3417 | T118: 45296 | W118: 4349 | X118: Customer 4 | Y118: EMBEDDED | Z118: 3915 | AA118: 4893 | AB118: 45473 | AM118: 3616 | AN118: Customer 1 | AO118: WORKSTATION | AP118: 1119 | AQ118: 4880 | AR118: 45442
O119: 118 | P119: Customer 7 | Q119: DESKTOP | R119: 2658 | S119: 2979 | T119: 45296 | W119: 1617 | X119: Customer 5 | Y119: MOBILE | Z119: 3914 | AA119: 1359 | AB119: 45359 | AM119: 3961 | AN119: Customer 5 | AO119: WORKSTATION | AP119: 1119 | AQ119: 102 | AR119: 45456
O120: 119 | P120: Customer 4 | Q120: DESKTOP | R120: 1162 | S120: 3687 | T120: 45296 | W120: 1894 | X120: Customer 2 | Y120: WORKSTATION | Z120: 3914 | AA120: 921 | AB120: 45370 | AM120: 4282 | AN120: Customer 10 | AO120: DESKTOP | AP120: 1118 | AQ120: 3972 | AR120: 45470
O121: 120 | P121: Customer 15 | Q121: MOBILE | R121: 3921 | S121: 145 | T121: 45296 | W121: 343 | X121: Customer 14 | Y121: DESKTOP | Z121: 3912 | AA121: 1379 | AB121: 45306 | AM121: 2162 | AN121: Customer 7 | AO121: DESKTOP | AP121: 1116 | AQ121: 2948 | AR121: 45382
...

Sheet Summary
A1: Summary Dashboard | L1: Top 10 Value1 | S1: Interactive Dropdowns | AA1: Helper Cells Interactive Dropdowns
A2: Total Value1 | B2: =SUM(Clean_Data!$S$2:$S$5001) -> 10033070 | L2: Final_ID | M2: Customer | N2: Program | O2: Value1 | P2: Value2 | Q2: Date | S2: Customer Filter | T2: Customer 6 | AA2: Customer_List | AB2: Program_List | AC2: Bucket_List
A3: Total Value2 | B3: =SUM(Clean_Data!$T$2:$T$5001) -> 12844707 | L3: {=_xlfn.TAKE(_xlfn._xlws.SORT(Clean_Data!$P$2:$U$5001, 4, -1), 10)} -> 514 | M3: Customer 9 | N3: MOBILE | O3: 4000 | P3: 4777 | Q3: 45313 | S3: Program Filter | T3: WORKSTATION | AA3: {=_xlfn.UNIQUE(Clean_Data!$Q$2:$Q$5001)} -> Customer 6 | AB3: {=_xlfn.UNIQUE(Clean_Data!$R$2:$R$5001)} -> DESKTOP | AC3: {=_xlfn.UNIQUE(Clean_Data!$V$2:$V$5001)} -> Medium
A4: Average Value1 | B4: =AVERAGE(Clean_Data!$S$2:$S$5001) -> 2006.614 | L4: 3611 | M4: Customer 12 | N4: MOBILE | O4: 4000 | P4: 990 | Q4: 45442 | S4: Bucket Filter | T4: Medium | AA4: Customer 2 | AB4: WORKSTATION | AC4: High
A5: Earliest Date | B5: =MIN(Clean_Data!$U$2:$U$5001) -> 45292 | L5: 3847 | M5: Customer 13 | N5: MOBILE | O5: 4000 | P5: 3410 | Q5: 45452 | AA5: Customer 8 | AB5: EMBEDDED | AC5: Low
A6: Latest Date | B6: =MAX(Clean_Data!$U$2:$U$5001) -> 46025 | L6: 3476 | M6: Customer 13 | N6: WORKSTATION | O6: 3999 | P6: 4459 | Q6: 45436 | S6: Final_ID | T6: Customer | U6: Program | V6: Value1 | W6: Value2 | X6: Date | AA6: Customer 13 | AB6: MOBILE
A7: Number of Customers | B7: =COUNTA(_xlfn.UNIQUE(Clean_Data!$Q$2:$Q$5001)) -> 15 | L7: 4806 | M7: Customer 7 | N7: DESKTOP | O7: 3998 | P7: 1428 | Q7: 45492 | S7: {=_xlfn._xlws.FILTER(Clean_Data!$P$2:$U$5001, (Clean_Data!$Q$2:$Q$5001 = $T$2) * (Clean_Data!$R$2:$R$5001 = $T$3) * (Clean_Data!$V$2:$V$5001 = $T$4), "No matching rows")} -> 660 | T7: Customer 6 | U7: WORKSTATION | V7: 782 | W7: 3391 | X7: 45319 | AA7: Customer 10
A8: Number of Programs | B8: =COUNTA(_xlfn.UNIQUE(Clean_Data!$R$2:$R$5001)) -> 4 | L8: 3260 | M8: Customer 11 | N8: EMBEDDED | O8: 3997 | P8: 2519 | Q8: 45427 | S8: 873 | T8: Customer 6 | U8: WORKSTATION | V8: 879 | W8: 266 | X8: 45328 | AA8: Customer 12
L9: 174 | M9: Customer 2 | N9: DESKTOP | O9: 3996 | P9: 4378 | Q9: 45299 | S9: 987 | T9: Customer 6 | U9: WORKSTATION | V9: 961 | W9: 2795 | X9: 45333 | AA9: Customer 11
L10: 659 | M10: Customer 13 | N10: DESKTOP | O10: 3996 | P10: 4332 | Q10: 45319 | S10: 1233 | T10: Customer 6 | U10: WORKSTATION | V10: 1163 | W10: 4268 | X10: 45343 | AA10: Customer 1
A11: Summary by Customer | L11: 2805 | M11: Customer 13 | N11: DESKTOP | O11: 3996 | P11: 1391 | Q11: 45408 | S11: 1381 | T11: Customer 6 | U11: WORKSTATION | V11: 823 | W11: 1423 | X11: 45349 | AA11: Customer 15
A12: Customer | B12: Count | C12: Total Val1 | D12: Total Val2 | E12: Avg Val1 | F12: Min Date | G12: Max Date | H12: Bucket Mode | I12: Customer (Sorted) | J12: Total Val1 (Sorted) | L12: 4516 | M12: Customer 12 | N12: MOBILE | O12: 3996 | P12: 2537 | Q12: 45480 | S12: 1455 | T12: Customer 6 | U12: WORKSTATION | V12: 988 | W12: 1325 | X12: 45352 | AA12: Customer 14
A13: {=_xlfn.UNIQUE(Clean_Data!$Q$2:$Q$5001)} -> Customer 6 | B13: =COUNTIF(Clean_Data!$Q$2:$Q$5001, A13) -> 321 | C13: =SUMIF(Clean_Data!$Q$2:$Q$5001, A13, Clean_Data!$S$2:$S$5001) -> 646349 | D13: =SUMIF(Clean_Data!$Q$2:$Q$5001, A13, Clean_Data!$T$2:$T$5001) -> 831300 | E13: =AVERAGEIF(Clean_Data!$Q$2:$Q$5001, A13, Clean_Data!$S$2:$S$5001) -> 2013.5483 | F13: =_xlfn.MINIFS(Clean_Data!$U$2:$U$5001, Clean_Data!$Q$2:$Q$5001, A13) -> 45292 | G13: =_xlfn.MAXIFS(Clean_Data!$U$2:$U$5001, Clean_Data!$Q$2:$Q$5001, A13) -> 45499 | H13: =_xlfn.LET( _xlpm.cust, $A13, _xlpm.low, COUNTIFS(Clean_Data!$Q$2:$Q$5001, _xlpm.cust, Clean_Data!$V$2:$V$5001, "Low"), _xlpm.med, COUNTIFS(Clean_Data!$Q$2:$Q$5001, _xlpm.cust, Clean_Data!$V$2:$V$5001, "Medium"), _xlpm.hi, COUNTIFS(Clean_Data!$Q$2:$Q$5001, _xlpm.cust, Clean_Data!$V$2:$V$5001, "High"), _xlpm.maxC, MAX(_xlpm.low, _xlpm.med, _xlpm.hi), IF( _xlpm.maxC = 0, "", IF(_xlpm.maxC = _xlpm.low, "Low", IF(_xlpm.maxC = _xlpm.med, "Medium", "High") ) ) ) -> High | I13: {=_xlfn.XLOOKUP(_xlfn.ANCHORARRAY(J13), $C$13:$C$27, $A$13:$A$27)} -> Customer 11 | J13: {=_xlfn._xlws.SORT($C$13:INDEX($C$13:$C$27, COUNTA($A$13:$A$27)), , -1)} -> 727034 | S13: 1542 | T13: Customer 6 | U13: WORKSTATION | V13: 915 | W13: 4611 | X13: 45356 | AA13: Customer 5
A14: Customer 2 | B14: =COUNTIF(Clean_Data!$Q$2:$Q$5001, A14) -> 351 | C14: =SUMIF(Clean_Data!$Q$2:$Q$5001, A14, Clean_Data!$S$2:$S$5001) -> 702816 | D14: =SUMIF(Clean_Data!$Q$2:$Q$5001, A14, Clean_Data!$T$2:$T$5001) -> 913743 | E14: =AVERAGEIF(Clean_Data!$Q$2:$Q$5001, A14, Clean_Data!$S$2:$S$5001) -> 2002.3248 | F14: =_xlfn.MINIFS(Clean_Data!$U$2:$U$5001, Clean_Data!$Q$2:$Q$5001, A14) -> 45292 | G14: =_xlfn.MAXIFS(Clean_Data!$U$2:$U$5001, Clean_Data!$Q$2:$Q$5001, A14) -> 45499 | H14: =_xlfn.LET( _xlpm.cust, $A14, _xlpm.low, COUNTIFS(Clean_Data!$Q$2:$Q$5001, _xlpm.cust, Clean_Data!$V$2:$V$5001, "Low"), _xlpm.med, COUNTIFS(Clean_Data!$Q$2:$Q$5001, _xlpm.cust, Clean_Data!$V$2:$V$5001, "Medium"), _xlpm.hi, COUNTIFS(Clean_Data!$Q$2:$Q$5001, _xlpm.cust, Clean_Data!$V$2:$V$5001, "High"), _xlpm.maxC, MAX(_xlpm.low, _xlpm.med, _xlpm.hi), IF( _xlpm.maxC = 0, "", IF(_xlpm.maxC = _xlpm.low, "Low", IF(_xlpm.maxC = _xlpm.med, "Medium", "High") ) ) ) -> High | I14: Customer 13 | J14: 705688 | S14: 1948 | T14: Customer 6 | U14: WORKSTATION | V14: 998 | W14: 4135 | X14: 45373 | AA14: Customer 9
A15: Customer 8 | B15: =COUNTIF(Clean_Data!$Q$2:$Q$5001, A15) -> 335 | C15: =SUMIF(Clean_Data!$Q$2:$Q$5001, A15, Clean_Data!$S$2:$S$5001) -> 683483 | D15: =SUMIF(Clean_Data!$Q$2:$Q$5001, A15, Clean_Data!$T$2:$T$5001) -> 823483 | E15: =AVERAGEIF(Clean_Data!$Q$2:$Q$5001, A15, Clean_Data!$S$2:$S$5001) -> 2040.2478 | F15: =_xlfn.MINIFS(Clean_Data!$U$2:$U$5001, Clean_Data!$Q$2:$Q$5001, A15) -> 45292 | G15: =_xlfn.MAXIFS(Clean_Data!$U$2:$U$5001, Clean_Data!$Q$2:$Q$5001, A15) -> 45499 | H15: =_xlfn.LET( _xlpm.cust, $A15, _xlpm.low, COUNTIFS(Clean_Data!$Q$2:$Q$5001, _xlpm.cust, Clean_Data!$V$2:$V$5001, "Low"), _xlpm.med, COUNTIFS(Clean_Data!$Q$2:$Q$5001, _xlpm.cust, Clean_Data!$V$2:$V$5001, "Medium"), _xlpm.hi, COUNTIFS(Clean_Data!$Q$2:$Q$5001, _xlpm.cust, Clean_Data!$V$2:$V$5001, "High"), _xlpm.maxC, MAX(_xlpm.low, _xlpm.med, _xlpm.hi), IF( _xlpm.maxC = 0, "", IF(_xlpm.maxC = _xlpm.low, "Low", IF(_xlpm.maxC = _xlpm.med, "Medium", "High") ) ) ) -> High | I15: Customer 4 | J15: 703527 | L15: Monthly Summary | S15: 2194 | T15: Customer 6 | U15: WORKSTATION | V15: 665 | W15: 1896 | X15: 45383 | AA15: Customer 3
A16: Customer 13 | B16: =COUNTIF(Clean_Data!$Q$2:$Q$5001, A16) -> 332 | C16: =SUMIF(Clean_Data!$Q$2:$Q$5001, A16, Clean_Data!$S$2:$S$5001) -> 705688 | D16: =SUMIF(Clean_Data!$Q$2:$Q$5001, A16, Clean_Data!$T$2:$T$5001) -> 870906 | E16: =AVERAGEIF(Clean_Data!$Q$2:$Q$5001, A16, Clean_Data!$S$2:$S$5001) -> 2125.5663 | F16: =_xlfn.MINIFS(Clean_Data!$U$2:$U$5001, Clean_Data!$Q$2:$Q$5001, A16) -> 45292 | G16: =_xlfn.MAXIFS(Clean_Data!$U$2:$U$5001, Clean_Data!$Q$2:$Q$5001, A16) -> 45660 | H16: =_xlfn.LET( _xlpm.cust, $A16, _xlpm.low, COUNTIFS(Clean_Data!$Q$2:$Q$5001, _xlpm.cust, Clean_Data!$V$2:$V$5001, "Low"), _xlpm.med, COUNTIFS(Clean_Data!$Q$2:$Q$5001, _xlpm.cust, Clean_Data!$V$2:$V$5001, "Medium"), _xlpm.hi, COUNTIFS(Clean_Data!$Q$2:$Q$5001, _xlpm.cust, Clean_Data!$V$2:$V$5001, "High"), _xlpm.maxC, MAX(_xlpm.low, _xlpm.med, _xlpm.hi), IF( _xlpm.maxC = 0, "", IF(_xlpm.maxC = _xlpm.low, "Low", IF(_xlpm.maxC = _xlpm.med, "Medium", "High") ) ) ) -> High | I16: Customer 2 | J16: 702816 | L16: Month | M16: Total Value1 | N16: Total Value2 | O16: Count | P16: Avg Value1 | S16: 2694 | T16: Customer 6 | U16: WORKSTATION | V16: 725 | W16: 2358 | X16: 45404 | AA16: Customer 7
A17: Customer 10 | B17: =COUNTIF(Clean_Data!$Q$2:$Q$5001, A17) -> 327 | C17: =SUMIF(Clean_Data!$Q$2:$Q$5001, A17, Clean_Data!$S$2:$S$5001) -> 630278 | D17: =SUMIF(Clean_Data!$Q$2:$Q$5001, A17, Clean_Data!$T$2:$T$5001) -> 815356 | E17: =AVERAGEIF(Clean_Data!$Q$2:$Q$5001, A17, Clean_Data!$S$2:$S$5001) -> 1927.4557 | F17: =_xlfn.MINIFS(Clean_Data!$U$2:$U$5001, Clean_Data!$Q$2:$Q$5001, A17) -> 45292 | G17: =_xlfn.MAXIFS(Clean_Data!$U$2:$U$5001, Clean_Data!$Q$2:$Q$5001, A17) -> 45498 | H17: =_xlfn.LET( _xlpm.cust, $A17, _xlpm.low, COUNTIFS(Clean_Data!$Q$2:$Q$5001, _xlpm.cust, Clean_Data!$V$2:$V$5001, "Low"), _xlpm.med, COUNTIFS(Clean_Data!$Q$2:$Q$5001, _xlpm.cust, Clean_Data!$V$2:$V$5001, "Medium"), _xlpm.hi, COUNTIFS(Clean_Data!$Q$2:$Q$5001, _xlpm.cust, Clean_Data!$V$2:$V$5001, "High"), _xlpm.maxC, MAX(_xlpm.low, _xlpm.med, _xlpm.hi), IF( _xlpm.maxC = 0, "", IF(_xlpm.maxC = _xlpm.low, "Low", IF(_xlpm.maxC = _xlpm.med, "Medium", "High") ) ) ) -> High | I17: Customer 1 | J17: 700171 | L17: {=_xlfn._xlws.SORT(_xlfn.UNIQUE(Clean_Data!$W$2:$W$5001))} -> 2024-01 | M17: =SUMIFS( Clean_Data!$S$2:$S$5001, Clean_Data!$W$2:$W$5001, L17 ) -> 1516648 | N17: =SUMIFS( Clean_Data!$T$2:$T$5001, Clean_Data!$W$2:$W$5001, L17 ) -> 1888398 | O17: =COUNTIFS( Clean_Data!$W$2:$W$5001, L17 ) -> 742 | P17: =AVERAGEIFS( Clean_Data!$S$2:$S$5001, Clean_Data!$W$2:$W$5001, L17 ) -> 2044 | S17: 2747 | T17: Customer 6 | U17: WORKSTATION | V17: 1141 | W17: 1501 | X17: 45406 | AA17: Customer 4
A18: Customer 12 | B18: =COUNTIF(Clean_Data!$Q$2:$Q$5001, A18) -> 338 | C18: =SUMIF(Clean_Data!$Q$2:$Q$5001, A18, Clean_Data!$S$2:$S$5001) -> 664484 | D18: =SUMIF(Clean_Data!$Q$2:$Q$5001, A18, Clean_Data!$T$2:$T$5001) -> 898058 | E18: =AVERAGEIF(Clean_Data!$Q$2:$Q$5001, A18, Clean_Data!$S$2:$S$5001) -> 1965.929 | F18: =_xlfn.MINIFS(Clean_Data!$U$2:$U$5001, Clean_Data!$Q$2:$Q$5001, A18) -> 45292 | G18: =_xlfn.MAXIFS(Clean_Data!$U$2:$U$5001, Clean_Data!$Q$2:$Q$5001, A18) -> 46025 | H18: =_xlfn.LET( _xlpm.cust, $A18, _xlpm.low, COUNTIFS(Clean_Data!$Q$2:$Q$5001, _xlpm.cust, Clean_Data!$V$2:$V$5001, "Low"), _xlpm.med, COUNTIFS(Clean_Data!$Q$2:$Q$5001, _xlpm.cust, Clean_Data!$V$2:$V$5001, "Medium"), _xlpm.hi, COUNTIFS(Clean_Data!$Q$2:$Q$5001, _xlpm.cust, Clean_Data!$V$2:$V$5001, "High"), _xlpm.maxC, MAX(_xlpm.low, _xlpm.med, _xlpm.hi), IF( _xlpm.maxC = 0, "", IF(_xlpm.maxC = _xlpm.low, "Low", IF(_xlpm.maxC = _xlpm.med, "Medium", "High") ) ) ) -> High | I18: Customer 7 | J18: 685782 | L18: 2024-02 | M18: =SUMIFS( Clean_Data!$S$2:$S$5001, Clean_Data!$W$2:$W$5001, L18 ) -> 1350320 | N18: =SUMIFS( Clean_Data!$T$2:$T$5001, Clean_Data!$W$2:$W$5001, L18 ) -> 1709251 | O18: =COUNTIFS( Clean_Data!$W$2:$W$5001, L18 ) -> 696 | P18: =AVERAGEIFS( Clean_Data!$S$2:$S$5001, Clean_Data!$W$2:$W$5001, L18 ) -> 1940.1149 | S18: 2844 | T18: Customer 6 | U18: WORKSTATION | V18: 598 | W18: 1011 | X18: 45410
A19: Customer 11 | B19: =COUNTIF(Clean_Data!$Q$2:$Q$5001, A19) -> 360 | C19: =SUMIF(Clean_Data!$Q$2:$Q$5001, A19, Clean_Data!$S$2:$S$5001) -> 727034 | D19: =SUMIF(Clean_Data!$Q$2:$Q$5001, A19, Clean_Data!$T$2:$T$5001) -> 956909 | E19: =AVERAGEIF(Clean_Data!$Q$2:$Q$5001, A19, Clean_Data!$S$2:$S$5001) -> 2019.5389 | F19: =_xlfn.MINIFS(Clean_Data!$U$2:$U$5001, Clean_Data!$Q$2:$Q$5001, A19) -> 45292 | G19: =_xlfn.MAXIFS(Clean_Data!$U$2:$U$5001, Clean_Data!$Q$2:$Q$5001, A19) -> 45500 | H19: =_xlfn.LET( _xlpm.cust, $A19, _xlpm.low, COUNTIFS(Clean_Data!$Q$2:$Q$5001, _xlpm.cust, Clean_Data!$V$2:$V$5001, "Low"), _xlpm.med, COUNTIFS(Clean_Data!$Q$2:$Q$5001, _xlpm.cust, Clean_Data!$V$2:$V$5001, "Medium"), _xlpm.hi, COUNTIFS(Clean_Data!$Q$2:$Q$5001, _xlpm.cust, Clean_Data!$V$2:$V$5001, "High"), _xlpm.maxC, MAX(_xlpm.low, _xlpm.med, _xlpm.hi), IF( _xlpm.maxC = 0, "", IF(_xlpm.maxC = _xlpm.low, "Low", IF(_xlpm.maxC = _xlpm.med, "Medium", "High") ) ) ) -> High | I19: Customer 8 | J19: 683483 | L19: 2024-03 | M19: =SUMIFS( Clean_Data!$S$2:$S$5001, Clean_Data!$W$2:$W$5001, L19 ) -> 1501991 | N19: =SUMIFS( Clean_Data!$T$2:$T$5001, Clean_Data!$W$2:$W$5001, L19 ) -> 1919758 | O19: =COUNTIFS( Clean_Data!$W$2:$W$5001, L19 ) -> 744 | P19: =AVERAGEIFS( Clean_Data!$S$2:$S$5001, Clean_Data!$W$2:$W$5001, L19 ) -> 2018.8051 | S19: 2961 | T19: Customer 6 | U19: WORKSTATION | V19: 929 | W19: 3730 | X19: 45415
A20: Customer 1 | B20: =COUNTIF(Clean_Data!$Q$2:$Q$5001, A20) -> 358 | C20: =SUMIF(Clean_Data!$Q$2:$Q$5001, A20, Clean_Data!$S$2:$S$5001) -> 700171 | D20: =SUMIF(Clean_Data!$Q$2:$Q$5001, A20, Clean_Data!$T$2:$T$5001) -> 901533 | E20: =AVERAGEIF(Clean_Data!$Q$2:$Q$5001, A20, Clean_Data!$S$2:$S$5001) -> 1955.7849 | F20: =_xlfn.MINIFS(Clean_Data!$U$2:$U$5001, Clean_Data!$Q$2:$Q$5001, A20) -> 45292 | G20: =_xlfn.MAXIFS(Clean_Data!$U$2:$U$5001, Clean_Data!$Q$2:$Q$5001, A20) -> 45500 | H20: =_xlfn.LET( _xlpm.cust, $A20, _xlpm.low, COUNTIFS(Clean_Data!$Q$2:$Q$5001, _xlpm.cust, Clean_Data!$V$2:$V$5001, "Low"), _xlpm.med, COUNTIFS(Clean_Data!$Q$2:$Q$5001, _xlpm.cust, Clean_Data!$V$2:$V$5001, "Medium"), _xlpm.hi, COUNTIFS(Clean_Data!$Q$2:$Q$5001, _xlpm.cust, Clean_Data!$V$2:$V$5001, "High"), _xlpm.maxC, MAX(_xlpm.low, _xlpm.med, _xlpm.hi), IF( _xlpm.maxC = 0, "", IF(_xlpm.maxC = _xlpm.low, "Low", IF(_xlpm.maxC = _xlpm.med, "Medium", "High") ) ) ) -> High | I20: Customer 5 | J20: 668853 | L20: 2024-04 | M20: =SUMIFS( Clean_Data!$S$2:$S$5001, Clean_Data!$W$2:$W$5001, L20 ) -> 1421118 | N20: =SUMIFS( Clean_Data!$T$2:$T$5001, Clean_Data!$W$2:$W$5001, L20 ) -> 1854449 | O20: =COUNTIFS( Clean_Data!$W$2:$W$5001, L20 ) -> 721 | P20: =AVERAGEIFS( Clean_Data!$S$2:$S$5001, Clean_Data!$W$2:$W$5001, L20 ) -> 1971.0374 | S20: 3118 | T20: Customer 6 | U20: WORKSTATION | V20: 816 | W20: 4220 | X20: 45421
A21: Customer 15 | B21: =COUNTIF(Clean_Data!$Q$2:$Q$5001, A21) -> 307 | C21: =SUMIF(Clean_Data!$Q$2:$Q$5001, A21, Clean_Data!$S$2:$S$5001) -> 607887 | D21: =SUMIF(Clean_Data!$Q$2:$Q$5001, A21, Clean_Data!$T$2:$T$5001) -> 773556 | E21: =AVERAGEIF(Clean_Data!$Q$2:$Q$5001, A21, Clean_Data!$S$2:$S$5001) -> 1980.0879 | F21: =_xlfn.MINIFS(Clean_Data!$U$2:$U$5001, Clean_Data!$Q$2:$Q$5001, A21) -> 45293 | G21: =_xlfn.MAXIFS(Clean_Data!$U$2:$U$5001, Clean_Data!$Q$2:$Q$5001, A21) -> 45499 | H21: =_xlfn.LET( _xlpm.cust, $A21, _xlpm.low, COUNTIFS(Clean_Data!$Q$2:$Q$5001, _xlpm.cust, Clean_Data!$V$2:$V$5001, "Low"), _xlpm.med, COUNTIFS(Clean_Data!$Q$2:$Q$5001, _xlpm.cust, Clean_Data!$V$2:$V$5001, "Medium"), _xlpm.hi, COUNTIFS(Clean_Data!$Q$2:$Q$5001, _xlpm.cust, Clean_Data!$V$2:$V$5001, "High"), _xlpm.maxC, MAX(_xlpm.low, _xlpm.med, _xlpm.hi), IF( _xlpm.maxC = 0, "", IF(_xlpm.maxC = _xlpm.low, "Low", IF(_xlpm.maxC = _xlpm.med, "Medium", "High") ) ) ) -> High | I21: Customer 12 | J21: 664484 | L21: 2024-05 | M21: =SUMIFS( Clean_Data!$S$2:$S$5001, Clean_Data!$W$2:$W$5001, L21 ) -> 1492622 | N21: =SUMIFS( Clean_Data!$T$2:$T$5001, Clean_Data!$W$2:$W$5001, L21 ) -> 1882149 | O21: =COUNTIFS( Clean_Data!$W$2:$W$5001, L21 ) -> 744 | P21: =AVERAGEIFS( Clean_Data!$S$2:$S$5001, Clean_Data!$W$2:$W$5001, L21 ) -> 2006.2124 | S21: 3208 | T21: Customer 6 | U21: WORKSTATION | V21: 769 | W21: 2904 | X21: 45425
A22: Customer 14 | B22: =COUNTIF(Clean_Data!$Q$2:$Q$5001, A22) -> 306 | C22: =SUMIF(Clean_Data!$Q$2:$Q$5001, A22, Clean_Data!$S$2:$S$5001) -> 648528 | D22: =SUMIF(Clean_Data!$Q$2:$Q$5001, A22, Clean_Data!$T$2:$T$5001) -> 788441 | E22: =AVERAGEIF(Clean_Data!$Q$2:$Q$5001, A22, Clean_Data!$S$2:$S$5001) -> 2119.3725 | F22: =_xlfn.MINIFS(Clean_Data!$U$2:$U$5001, Clean_Data!$Q$2:$Q$5001, A22) -> 45293 | G22: =_xlfn.MAXIFS(Clean_Data!$U$2:$U$5001, Clean_Data!$Q$2:$Q$5001, A22) -> 45500 | H22: =_xlfn.LET( _xlpm.cust, $A22, _xlpm.low, COUNTIFS(Clean_Data!$Q$2:$Q$5001, _xlpm.cust, Clean_Data!$V$2:$V$5001, "Low"), _xlpm.med, COUNTIFS(Clean_Data!$Q$2:$Q$5001, _xlpm.cust, Clean_Data!$V$2:$V$5001, "Medium"), _xlpm.hi, COUNTIFS(Clean_Data!$Q$2:$Q$5001, _xlpm.cust, Clean_Data!$V$2:$V$5001, "High"), _xlpm.maxC, MAX(_xlpm.low, _xlpm.med, _xlpm.hi), IF( _xlpm.maxC = 0, "", IF(_xlpm.maxC = _xlpm.low, "Low", IF(_xlpm.maxC = _xlpm.med, "Medium", "High") ) ) ) -> High | I22: Customer 14 | J22: 648528 | L22: 2024-06 | M22: =SUMIFS( Clean_Data!$S$2:$S$5001, Clean_Data!$W$2:$W$5001, L22 ) -> 1498178 | N22: =SUMIFS( Clean_Data!$T$2:$T$5001, Clean_Data!$W$2:$W$5001, L22 ) -> 1932890 | O22: =COUNTIFS( Clean_Data!$W$2:$W$5001, L22 ) -> 720 | P22: =AVERAGEIFS( Clean_Data!$S$2:$S$5001, Clean_Data!$W$2:$W$5001, L22 ) -> 2080.8028 | S22: 3299 | T22: Customer 6 | U22: WORKSTATION | V22: 775 | W22: 3213 | X22: 45429
A23: Customer 5 | B23: =COUNTIF(Clean_Data!$Q$2:$Q$5001, A23) -> 354 | C23: =SUMIF(Clean_Data!$Q$2:$Q$5001, A23, Clean_Data!$S$2:$S$5001) -> 668853 | D23: =SUMIF(Clean_Data!$Q$2:$Q$5001, A23, Clean_Data!$T$2:$T$5001) -> 879949 | E23: =AVERAGEIF(Clean_Data!$Q$2:$Q$5001, A23, Clean_Data!$S$2:$S$5001) -> 1889.4153 | F23: =_xlfn.MINIFS(Clean_Data!$U$2:$U$5001, Clean_Data!$Q$2:$Q$5001, A23) -> 45293 | G23: =_xlfn.MAXIFS(Clean_Data!$U$2:$U$5001, Clean_Data!$Q$2:$Q$5001, A23) -> 45500 | H23: =_xlfn.LET( _xlpm.cust, $A23, _xlpm.low, COUNTIFS(Clean_Data!$Q$2:$Q$5001, _xlpm.cust, Clean_Data!$V$2:$V$5001, "Low"), _xlpm.med, COUNTIFS(Clean_Data!$Q$2:$Q$5001, _xlpm.cust, Clean_Data!$V$2:$V$5001, "Medium"), _xlpm.hi, COUNTIFS(Clean_Data!$Q$2:$Q$5001, _xlpm.cust, Clean_Data!$V$2:$V$5001, "High"), _xlpm.maxC, MAX(_xlpm.low, _xlpm.med, _xlpm.hi), IF( _xlpm.maxC = 0, "", IF(_xlpm.maxC = _xlpm.low, "Low", IF(_xlpm.maxC = _xlpm.med, "Medium", "High") ) ) ) -> High | I23: Customer 6 | J23: 646349 | L23: 2024-07 | M23: =SUMIFS( Clean_Data!$S$2:$S$5001, Clean_Data!$W$2:$W$5001, L23 ) -> 1251041 | N23: =SUMIFS( Clean_Data!$T$2:$T$5001, Clean_Data!$W$2:$W$5001, L23 ) -> 1653350 | O23: =COUNTIFS( Clean_Data!$W$2:$W$5001, L23 ) -> 631 | P23: =AVERAGEIFS( Clean_Data!$S$2:$S$5001, Clean_Data!$W$2:$W$5001, L23 ) -> 1982.6323 | S23: 3600 | T23: Customer 6 | U23: WORKSTATION | V23: 957 | W23: 1166 | X23: 45441
A24: Customer 9 | B24: =COUNTIF(Clean_Data!$Q$2:$Q$5001, A24) -> 320 | C24: =SUMIF(Clean_Data!$Q$2:$Q$5001, A24, Clean_Data!$S$2:$S$5001) -> 620977 | D24: =SUMIF(Clean_Data!$Q$2:$Q$5001, A24, Clean_Data!$T$2:$T$5001) -> 788768 | E24: =AVERAGEIF(Clean_Data!$Q$2:$Q$5001, A24, Clean_Data!$S$2:$S$5001) -> 1940.5531 | F24: =_xlfn.MINIFS(Clean_Data!$U$2:$U$5001, Clean_Data!$Q$2:$Q$5001, A24) -> 45293 | G24: =_xlfn.MAXIFS(Clean_Data!$U$2:$U$5001, Clean_Data!$Q$2:$Q$5001, A24) -> 45500 | H24: =_xlfn.LET( _xlpm.cust, $A24, _xlpm.low, COUNTIFS(Clean_Data!$Q$2:$Q$5001, _xlpm.cust, Clean_Data!$V$2:$V$5001, "Low"), _xlpm.med, COUNTIFS(Clean_Data!$Q$2:$Q$5001, _xlpm.cust, Clean_Data!$V$2:$V$5001, "Medium"), _xlpm.hi, COUNTIFS(Clean_Data!$Q$2:$Q$5001, _xlpm.cust, Clean_Data!$V$2:$V$5001, "High"), _xlpm.maxC, MAX(_xlpm.low, _xlpm.med, _xlpm.hi), IF( _xlpm.maxC = 0, "", IF(_xlpm.maxC = _xlpm.low, "Low", IF(_xlpm.maxC = _xlpm.med, "Medium", "High") ) ) ) -> High | I24: Customer 3 | J24: 637213 | L24: 2025-01 | M24: =SUMIFS( Clean_Data!$S$2:$S$5001, Clean_Data!$W$2:$W$5001, L24 ) -> 1015 | N24: =SUMIFS( Clean_Data!$T$2:$T$5001, Clean_Data!$W$2:$W$5001, L24 ) -> 3306 | O24: =COUNTIFS( Clean_Data!$W$2:$W$5001, L24 ) -> 1 | P24: =AVERAGEIFS( Clean_Data!$S$2:$S$5001, Clean_Data!$W$2:$W$5001, L24 ) -> 1015 | S24: 3808 | T24: Customer 6 | U24: WORKSTATION | V24: 671 | W24: 2402 | X24: 45450
A25: Customer 3 | B25: =COUNTIF(Clean_Data!$Q$2:$Q$5001, A25) -> 320 | C25: =SUMIF(Clean_Data!$Q$2:$Q$5001, A25, Clean_Data!$S$2:$S$5001) -> 637213 | D25: =SUMIF(Clean_Data!$Q$2:$Q$5001, A25, Clean_Data!$T$2:$T$5001) -> 856638 | E25: =AVERAGEIF(Clean_Data!$Q$2:$Q$5001, A25, Clean_Data!$S$2:$S$5001) -> 1991.2906 | F25: =_xlfn.MINIFS(Clean_Data!$U$2:$U$5001, Clean_Data!$Q$2:$Q$5001, A25) -> 45293 | G25: =_xlfn.MAXIFS(Clean_Data!$U$2:$U$5001, Clean_Data!$Q$2:$Q$5001, A25) -> 45499 | H25: =_xlfn.LET( _xlpm.cust, $A25, _xlpm.low, COUNTIFS(Clean_Data!$Q$2:$Q$5001, _xlpm.cust, Clean_Data!$V$2:$V$5001, "Low"), _xlpm.med, COUNTIFS(Clean_Data!$Q$2:$Q$5001, _xlpm.cust, Clean_Data!$V$2:$V$5001, "Medium"), _xlpm.hi, COUNTIFS(Clean_Data!$Q$2:$Q$5001, _xlpm.cust, Clean_Data!$V$2:$V$5001, "High"), _xlpm.maxC, MAX(_xlpm.low, _xlpm.med, _xlpm.hi), IF( _xlpm.maxC = 0, "", IF(_xlpm.maxC = _xlpm.low, "Low", IF(_xlpm.maxC = _xlpm.med, "Medium", "High") ) ) ) -> High | I25: Customer 10 | J25: 630278 | L25: 2026-01 | M25: =SUMIFS( Clean_Data!$S$2:$S$5001, Clean_Data!$W$2:$W$5001, L25 ) -> 137 | N25: =SUMIFS( Clean_Data!$T$2:$T$5001, Clean_Data!$W$2:$W$5001, L25 ) -> 1156 | O25: =COUNTIFS( Clean_Data!$W$2:$W$5001, L25 ) -> 1 | P25: =AVERAGEIFS( Clean_Data!$S$2:$S$5001, Clean_Data!$W$2:$W$5001, L25 ) -> 137 | S25: 4077 | T25: Customer 6 | U25: WORKSTATION | V25: 719 | W25: 1302 | X25: 45461
A26: Customer 7 | B26: =COUNTIF(Clean_Data!$Q$2:$Q$5001, A26) -> 324 | C26: =SUMIF(Clean_Data!$Q$2:$Q$5001, A26, Clean_Data!$S$2:$S$5001) -> 685782 | D26: =SUMIF(Clean_Data!$Q$2:$Q$5001, A26, Clean_Data!$T$2:$T$5001) -> 848079 | E26: =AVERAGEIF(Clean_Data!$Q$2:$Q$5001, A26, Clean_Data!$S$2:$S$5001) -> 2116.6111 | F26: =_xlfn.MINIFS(Clean_Data!$U$2:$U$5001, Clean_Data!$Q$2:$Q$5001, A26) -> 45293 | G26: =_xlfn.MAXIFS(Clean_Data!$U$2:$U$5001, Clean_Data!$Q$2:$Q$5001, A26) -> 45498 | H26: =_xlfn.LET( _xlpm.cust, $A26, _xlpm.low, COUNTIFS(Clean_Data!$Q$2:$Q$5001, _xlpm.cust, Clean_Data!$V$2:$V$5001, "Low"), _xlpm.med, COUNTIFS(Clean_Data!$Q$2:$Q$5001, _xlpm.cust, Clean_Data!$V$2:$V$5001, "Medium"), _xlpm.hi, COUNTIFS(Clean_Data!$Q$2:$Q$5001, _xlpm.cust, Clean_Data!$V$2:$V$5001, "High"), _xlpm.maxC, MAX(_xlpm.low, _xlpm.med, _xlpm.hi), IF( _xlpm.maxC = 0, "", IF(_xlpm.maxC = _xlpm.low, "Low", IF(_xlpm.maxC = _xlpm.med, "Medium", "High") ) ) ) -> High | I26: Customer 9 | J26: 620977
A27: Customer 4 | B27: =COUNTIF(Clean_Data!$Q$2:$Q$5001, A27) -> 347 | C27: =SUMIF(Clean_Data!$Q$2:$Q$5001, A27, Clean_Data!$S$2:$S$5001) -> 703527 | D27: =SUMIF(Clean_Data!$Q$2:$Q$5001, A27, Clean_Data!$T$2:$T$5001) -> 897988 | E27: =AVERAGEIF(Clean_Data!$Q$2:$Q$5001, A27, Clean_Data!$S$2:$S$5001) -> 2027.4553 | F27: =_xlfn.MINIFS(Clean_Data!$U$2:$U$5001, Clean_Data!$Q$2:$Q$5001, A27) -> 45294 | G27: =_xlfn.MAXIFS(Clean_Data!$U$2:$U$5001, Clean_Data!$Q$2:$Q$5001, A27) -> 45500 | H27: =_xlfn.LET( _xlpm.cust, $A27, _xlpm.low, COUNTIFS(Clean_Data!$Q$2:$Q$5001, _xlpm.cust, Clean_Data!$V$2:$V$5001, "Low"), _xlpm.med, COUNTIFS(Clean_Data!$Q$2:$Q$5001, _xlpm.cust, Clean_Data!$V$2:$V$5001, "Medium"), _xlpm.hi, COUNTIFS(Clean_Data!$Q$2:$Q$5001, _xlpm.cust, Clean_Data!$V$2:$V$5001, "High"), _xlpm.maxC, MAX(_xlpm.low, _xlpm.med, _xlpm.hi), IF( _xlpm.maxC = 0, "", IF(_xlpm.maxC = _xlpm.low, "Low", IF(_xlpm.maxC = _xlpm.med, "Medium", "High") ) ) ) -> High | I27: Customer 15 | J27: 607887
L28: Yearly Summary
L29: Year | M29: Total Value1 | N29: Total Value2 | O29: Count | P29: Avg Value1
L30: {=_xlfn.UNIQUE(YEAR(Clean_Data!$U$2:$U$5001))} -> 2024 | M30: =SUMIFS( Clean_Data!$S$2:$S$5001, Clean_Data!$X$2:$X$5001, L30 ) -> 10031918 | N30: =SUMIFS( Clean_Data!$T$2:$T$5001, Clean_Data!$X$2:$X$5001, L30 ) -> 12840245 | O30: =COUNTIFS( Clean_Data!$X$2:$X$5001, L30 ) -> 4998 | P30: =AVERAGEIFS( Clean_Data!$S$2:$S$5001, Clean_Data!$X$2:$X$5001, L30 ) -> 2007.1865
L31: 2025 | M31: =SUMIFS( Clean_Data!$S$2:$S$5001, Clean_Data!$X$2:$X$5001, L31 ) -> 1015 | N31: =SUMIFS( Clean_Data!$T$2:$T$5001, Clean_Data!$X$2:$X$5001, L31 ) -> 3306 | O31: =COUNTIFS( Clean_Data!$X$2:$X$5001, L31 ) -> 1 | P31: =AVERAGEIFS( Clean_Data!$S$2:$S$5001, Clean_Data!$X$2:$X$5001, L31 ) -> 1015
L32: 2026 | M32: =SUMIFS( Clean_Data!$S$2:$S$5001, Clean_Data!$X$2:$X$5001, L32 ) -> 137 | N32: =SUMIFS( Clean_Data!$T$2:$T$5001, Clean_Data!$X$2:$X$5001, L32 ) -> 1156 | O32: =COUNTIFS( Clean_Data!$X$2:$X$5001, L32 ) -> 1 | P32: =AVERAGEIFS( Clean_Data!$S$2:$S$5001, Clean_Data!$X$2:$X$5001, L32 ) -> 137
A37: Summary by Program
A38: Program | B38: Count | C38: Total Val1 | D38: Total Val2 | E38: Avg Val1 | F38: Min Date | G38: Max Date | H38: Bucket Mode | I38: Program_Sorted | J38: TotalVal1_Sorted_Prog
A39: {=_xlfn.UNIQUE(Clean_Data!$R$2:$R$5001)} -> DESKTOP | B39: =COUNTIF(Clean_Data!$R$2:$R$5001, A39) -> 1262 | C39: =SUMIF(Clean_Data!$R$2:$R$5001, A39, Clean_Data!$S$2:$S$5001) -> 2561413 | D39: =SUMIF(Clean_Data!$R$2:$R$5001, A39, Clean_Data!$T$2:$T$5001) -> 3240702 | E39: =AVERAGEIF(Clean_Data!$R$2:$R$5001, A39, Clean_Data!$S$2:$S$5001) -> 2029.6458 | F39: =_xlfn.MINIFS(Clean_Data!$U$2:$U$5001, Clean_Data!$Q$2:$Q$5001, A13) -> 45292 | G39: =_xlfn.MAXIFS(Clean_Data!$U$2:$U$5001, Clean_Data!$Q$2:$Q$5001, A13) -> 45499 | H39: =_xlfn.LET( _xlpm.prog, $A39, _xlpm.low, COUNTIFS(Clean_Data!$R$2:$R$5001, _xlpm.prog, Clean_Data!$V$2:$V$5001, "Low"), _xlpm.med, COUNTIFS(Clean_Data!$R$2:$R$5001, _xlpm.prog, Clean_Data!$V$2:$V$5001, "Medium"), _xlpm.hi, COUNTIFS(Clean_Data!$R$2:$R$5001, _xlpm.prog, Clean_Data!$V$2:$V$5001, "High"), _xlpm.maxC, MAX(_xlpm.low, _xlpm.med, _xlpm.hi), IF( _xlpm.maxC = 0, "", IF(_xlpm.maxC = _xlpm.low, "Low", IF(_xlpm.maxC = _xlpm.med, "Medium", "High") ) ) ) -> High | I39: {=_xlfn.XLOOKUP(_xlfn.ANCHORARRAY(J39), $C$39:$C$42, $A$39:$A$42)} -> DESKTOP | J39: {=_xlfn._xlws.SORT($C$39:INDEX($C$39:$C$42, COUNTA($A$39:$A$42)), , -1)} -> 2561413
